Workbook

Sheet Saisie
A1: Saisi des points | F1: Format tblRépondantsParJoueurs | K1: Format CSV
A2: # partie | B2: 6
A3: Équipe A | B3: Les Herbizarres | C3: =VLOOKUP(B3,tblÉquipes!$B$1:$E$8,4,FALSE()) -> 4 | F3: NoPartie | G3: NoÉquipe | H3: NoJoueur | I3: Points
A4: Équipe B | B4: Les Méthos précieux | C4: =VLOOKUP(B4,tblÉquipes!$B$1:$E$8,4,FALSE()) -> 5 | F4: {=_xlfn._xlws.FILTER(F18:I45,I18:I45>0)} -> 6 | G4: 4 | H4: 1 | I4: 115 | K4: =F4&","&G4&","&H4&","&I4 -> 6,4,1,115
F5: 6 | G5: 4 | H5: 2 | I5: 70 | K5: =F5&","&G5&","&H5&","&I5 -> 6,4,2,70
F6: 6 | G6: 4 | H6: 3 | I6: 70 | K6: =F6&","&G6&","&H6&","&I6 -> 6,4,3,70
A7: NoÉquipe | B7: NoJoueur | C7: Nom | D7: Points | F7: 6 | G7: 4 | H7: 11 | I7: 20 | K7: =F7&","&G7&","&H7&","&I7 -> 6,4,11,20
A8: {=_xlfn._xlws.FILTER(tblJoueurs!I:K,(tblJoueurs!I:I=$C$3)+(tblJoueurs!I:I=$C$4),"")} -> 4 | B8: 1 | C8: Sébastien Landry | D8: 115 | F8: 6 | G8: 4 | H8: 99 | I8: 20 | K8: =F8&","&G8&","&H8&","&I8 -> 6,4,99,20
A9: 4 | B9: 2 | C9: Frédéric Bédard | D9: 70 | F9: 6 | G9: 5 | H9: 1 | I9: 80 | K9: =F9&","&G9&","&H9&","&I9 -> 6,5,1,80
A10: 4 | B10: 3 | C10: Geneviève Ouellet | D10: 70 | F10: 6 | G10: 5 | H10: 2 | I10: 60 | K10: =F10&","&G10&","&H10&","&I10 -> 6,5,2,60
A11: 4 | B11: 4 | C11: Samuel Vézina | F11: 6 | G11: 5 | H11: 3 | I11: 40 | K11: =F11&","&G11&","&H11&","&I11 -> 6,5,3,40
A12: 4 | B12: 5 | C12: Jean-Dominique Morency | F12: 6 | G12: 5 | H12: 4 | I12: 40 | K12: =F12&","&G12&","&H12&","&I12 -> 6,5,4,40
A13: 4 | B13: 6 | C13: Stéphane Martineau | F13: 6 | G13: 5 | H13: 99 | I13: 40 | K13: =F13&","&G13&","&H13&","&I13 -> 6,5,99,40
A14: 4 | B14: 7 | C14: Michel Parenteau
A15: 4 | B15: 8 | C15: Caroline Pelletier
A16: 4 | B16: 9 | C16: Absent Absent | F16: Copie avec les bonnes colonnes
A17: 4 | B17: 10 | C17: Sylvain Coulombe | F17: NoPartie | G17: NoÉquipe | H17: NoJoueur | I17: Points
A18: 4 | B18: 11 | C18: Francis Demers | D18: 20 | F18: =$B$2 -> 6 | G18: =A8 -> 4 | H18: =B8 -> 1 | I18: =D8 -> 115
A19: 4 | B19: 99 | C19: NA Les Herbizarres | D19: 20 | F19: =$B$2 -> 6 | G19: =A9 -> 4 | H19: =B9 -> 2 | I19: =D9 -> 70
A20: 5 | B20: 1 | C20: Bruno Lapierre | D20: 80 | F20: =$B$2 -> 6 | G20: =A10 -> 4 | H20: =B10 -> 3 | I20: =D10 -> 70
A21: 5 | B21: 2 | C21: Julie Bernier | D21: 60 | F21: =$B$2 -> 6 | G21: =A11 -> 4 | H21: =B11 -> 4 | I21: =D11 -> 0
A22: 5 | B22: 3 | C22: Sylvain Perron | D22: 40 | F22: =$B$2 -> 6 | G22: =A12 -> 4 | H22: =B12 -> 5 | I22: =D12 -> 0
A23: 5 | B23: 4 | C23: Martin Sirois | D23: 40 | F23: =$B$2 -> 6 | G23: =A13 -> 4 | H23: =B13 -> 6 | I23: =D13 -> 0
A24: 5 | B24: 5 | C24: Didier Garriguet | F24: =$B$2 -> 6 | G24: =A14 -> 4 | H24: =B14 -> 7 | I24: =D14 -> 0
A25: 5 | B25: 6 | C25: Jean-Sébastien Provencal | F25: =$B$2 -> 6 | G25: =A15 -> 4 | H25: =B15 -> 8 | I25: =D15 -> 0
A26: 5 | B26: 7 | C26: Absent Absent | F26: =$B$2 -> 6 | G26: =A16 -> 4 | H26: =B16 -> 9 | I26: =D16 -> 0
A27: 5 | B27: 8 | C27: Marlène Savard | F27: =$B$2 -> 6 | G27: =A17 -> 4 | H27: =B17 -> 10 | I27: =D17 -> 0
A28: 5 | B28: 9 | C28: François Lavoie | F28: =$B$2 -> 6 | G28: =A18 -> 4 | H28: =B18 -> 11 | I28: =D18 -> 20
A29: 5 | B29: 99 | C29: NA Les Méthos précieux | D29: 40 | F29: =$B$2 -> 6 | G29: =A19 -> 4 | H29: =B19 -> 99 | I29: =D19 -> 20
A30: #N/A | B30: #N/A | C30: #N/A | F30: =$B$2 -> 6 | G30: =A20 -> 5 | H30: =B20 -> 1 | I30: =D20 -> 80
A31: #N/A | B31: #N/A | C31: #N/A | F31: =$B$2 -> 6 | G31: =A21 -> 5 | H31: =B21 -> 2 | I31: =D21 -> 60
A32: #N/A | B32: #N/A | C32: #N/A | F32: =$B$2 -> 6 | G32: =A22 -> 5 | H32: =B22 -> 3 | I32: =D22 -> 40
F33: =$B$2 -> 6 | G33: =A23 -> 5 | H33: =B23 -> 4 | I33: =D23 -> 40
F34: =$B$2 -> 6 | G34: =A24 -> 5 | H34: =B24 -> 5 | I34: =D24 -> 0
F35: =$B$2 -> 6 | G35: =A25 -> 5 | H35: =B25 -> 6 | I35: =D25 -> 0
F36: =$B$2 -> 6 | G36: =A26 -> 5 | H36: =B26 -> 7 | I36: =D26 -> 0
F37: =$B$2 -> 6 | G37: =A27 -> 5 | H37: =B27 -> 8 | I37: =D27 -> 0
F38: =$B$2 -> 6 | G38: =A28 -> 5 | H38: =B28 -> 9 | I38: =D28 -> 0
F39: =$B$2 -> 6 | G39: =A29 -> 5 | H39: =B29 -> 99 | I39: =D29 -> 40
F40: =$B$2 -> 6 | G40: =A30 -> #N/A | H40: =B30 -> #N/A | I40: =D30 -> 0
...

Sheet tblÉquipes
A1: NoÉquipe | B1: NomÉquipe | C1: PosFinale | D1: Carillon | E1: NoÉquipe2
A2: 1 | B2: Les Génies de la traduction | C2: NA | D2: 10 | E2: =tblÉquipes!$A2 -> 1
A3: 2 | B3: Les Bons Perdants | C3: NA | D3: 10 | E3: =tblÉquipes!$A3 -> 2
A4: 3 | B4: Les érudits en gerbe | C4: NA | D4: 10 | E4: =tblÉquipes!$A4 -> 3
A5: 4 | B5: Les Herbizarres | C5: NA | D5: 10 | E5: =tblÉquipes!$A5 -> 4
A6: 5 | B6: Les Méthos précieux | C6: NA | D6: 16 | E6: =tblÉquipes!$A6 -> 5
A7: 6 | B7: Les 12e meilleurs | C7: NA | D7: 10 | E7: =tblÉquipes!$A7 -> 6
A8: 7 | B8: Les Faciles à cuire | C8: NA | D8: 16 | E8: =tblÉquipes!$A8 -> 7

Sheet tblJoueurs
A1: NoÉquipe | B1: NoJoueur | C1: NomJoueur | D1: PrénomJoueur | E1: Alias | F1: Statut | G1: Icône | H1: PosActuelle | I1: NoÉquipe2 | J1: NoJoueur2 | K1: Nom complet
A2: 1 | B2: 1 | C2: Audet-Brazeau | D2: Stéphanie | E2: Stéphanie | F2: Capitaine | G2: 1 | H2: 1 | I2: =tblJoueurs!$A2 -> 1 | J2: =tblJoueurs!$B2 -> 1 | K2: =tblJoueurs!$D2 & " " &tblJoueurs!$C2 -> Stéphanie Audet-Brazeau | N2: 1
A3: 1 | B3: 2 | C3: Colpron | D3: Julia | E3: Julia | F3: Régulier | G3: 1 | H3: 4 | I3: =tblJoueurs!$A3 -> 1 | J3: =tblJoueurs!$B3 -> 2 | K3: =tblJoueurs!$D3 & " " &tblJoueurs!$C3 -> Julia Colpron
A4: 1 | B4: 3 | C4: Gamache | D4: Isabelle | E4: Isabelle | F4: Régulier | G4: 1 | H4: 2 | I4: =tblJoueurs!$A4 -> 1 | J4: =tblJoueurs!$B4 -> 3 | K4: =tblJoueurs!$D4 & " " &tblJoueurs!$C4 -> Isabelle Gamache
A5: 1 | B5: 4 | C5: Lachance | D5: Catherine | E5: Catherine | F5: Régulier | G5: 1 | H5: 3 | I5: =tblJoueurs!$A5 -> 1 | J5: =tblJoueurs!$B5 -> 4 | K5: =tblJoueurs!$D5 & " " &tblJoueurs!$C5 -> Catherine Lachance
A6: 1 | B6: 5 | C6: Vilandré | D6: Francis | E6: Francis | F6: Régulier | G6: 1 | H6: 0 | I6: =tblJoueurs!$A6 -> 1 | J6: =tblJoueurs!$B6 -> 5 | K6: =tblJoueurs!$D6 & " " &tblJoueurs!$C6 -> Francis Vilandré
A7: 1 | B7: 6 | C7: Sarrazin | D7: Julie | E7: Julie | F7: Régulier | G7: 1 | H7: 0 | I7: =tblJoueurs!$A7 -> 1 | J7: =tblJoueurs!$B7 -> 6 | K7: =tblJoueurs!$D7 & " " &tblJoueurs!$C7 -> Julie Sarrazin | N7: {=_xlfn._xlws.FILTER(A3:D15,A3:A15=1)} -> 1 | O7: 2 | P7: Colpron | Q7: Julia
A8: 1 | B8: 7 | C8: Absent | D8: Absent | E8: Absent | F8: Remplaçant | G8: 1 | H8: 0 | I8: =tblJoueurs!$A8 -> 1 | J8: =tblJoueurs!$B8 -> 7 | K8: =tblJoueurs!$D8 & " " &tblJoueurs!$C8 -> Absent Absent | N8: 1 | O8: 3 | P8: Gamache | Q8: Isabelle
A9: 1 | B9: 8 | C9: Fougères | D9: Émilie | E9: Émilie | F9: Remplaçant | G9: 1 | H9: 0 | I9: =tblJoueurs!$A9 -> 1 | J9: =tblJoueurs!$B9 -> 8 | K9: =tblJoueurs!$D9 & " " &tblJoueurs!$C9 -> Émilie Fougères | N9: 1 | O9: 4 | P9: Lachance | Q9: Catherine
A10: 1 | B10: 9 | C10: Loiselle | D10: Marc-Olivier | E10: Marc-Olivier | F10: Remplaçant | G10: 1 | H10: 0 | I10: =tblJoueurs!$A10 -> 1 | J10: =tblJoueurs!$B10 -> 9 | K10: =tblJoueurs!$D10 & " " &tblJoueurs!$C10 -> Marc-Olivier Loiselle | N10: 1 | O10: 5 | P10: Vilandré | Q10: Francis
A11: 1 | B11: 10 | C11: Sarrette | D11: Christian Frédéric | E11: Christian Frédéric | F11: Remplaçant | G11: 1 | H11: 0 | I11: =tblJoueurs!$A11 -> 1 | J11: =tblJoueurs!$B11 -> 10 | K11: =tblJoueurs!$D11 & " " &tblJoueurs!$C11 -> Christian Frédéric Sarrette | N11: 1 | O11: 6 | P11: Sarrazin | Q11: Julie
A12: 1 | B12: 99 | C12: Les Génies de la traduction | D12: NA | E12: Les Génies de la traduction | F12: Équipe | G12: 1 | H12: 0 | I12: =tblJoueurs!$A12 -> 1 | J12: =tblJoueurs!$B12 -> 99 | K12: =tblJoueurs!$D12 & " " &tblJoueurs!$C12 -> NA Les Génies de la traduction | N12: 1 | O12: 7 | P12: Absent | Q12: Absent
A13: 2 | B13: 1 | C13: Boisvert | D13: Steeve | E13: Steeve | F13: Capitaine | G13: 1 | H13: 1 | I13: =tblJoueurs!$A13 -> 2 | J13: =tblJoueurs!$B13 -> 1 | K13: =tblJoueurs!$D13 & " " &tblJoueurs!$C13 -> Steeve Boisvert | N13: 1 | O13: 8 | P13: Fougères | Q13: Émilie
A14: 2 | B14: 2 | C14: Perreault | D14: Samuel | E14: Samuel | F14: Régulier | G14: 1 | H14: 0 | I14: =tblJoueurs!$A14 -> 2 | J14: =tblJoueurs!$B14 -> 2 | K14: =tblJoueurs!$D14 & " " &tblJoueurs!$C14 -> Samuel Perreault | N14: 1 | O14: 9 | P14: Loiselle | Q14: Marc-Olivier
A15: 2 | B15: 3 | C15: Baillargeon | D15: Jonathan | E15: Jonathan | F15: Régulier | G15: 1 | H15: 4 | I15: =tblJoueurs!$A15 -> 2 | J15: =tblJoueurs!$B15 -> 3 | K15: =tblJoueurs!$D15 & " " &tblJoueurs!$C15 -> Jonathan Baillargeon
A16: 2 | B16: 4 | C16: Hardy | D16: Vincent | E16: Vincent | F16: Régulier | G16: 1 | H16: 2 | I16: =tblJoueurs!$A16 -> 2 | J16: =tblJoueurs!$B16 -> 4 | K16: =tblJoueurs!$D16 & " " &tblJoueurs!$C16 -> Vincent Hardy
A17: 2 | B17: 5 | C17: Paquin | D17: Nicole | E17: Nicole | F17: Remplaçant | G17: 1 | H17: 3 | I17: =tblJoueurs!$A17 -> 2 | J17: =tblJoueurs!$B17 -> 5 | K17: =tblJoueurs!$D17 & " " &tblJoueurs!$C17 -> Nicole Paquin
A18: 2 | B18: 6 | C18: Assoumou | D18: Franklin | E18: Franklin | F18: Remplaçant | G18: 1 | H18: 0 | I18: =tblJoueurs!$A18 -> 2 | J18: =tblJoueurs!$B18 -> 6 | K18: =tblJoueurs!$D18 & " " &tblJoueurs!$C18 -> Franklin Assoumou | M18: {=_xlfn._xlws.FILTER(J:L,I:I=1)} -> 1 | N18: Stéphanie Audet-Brazeau | O18: 0
A19: 2 | B19: 7 | C19: Sarrasin | D19: Marie-Hélène | E19: Marie-Hélène | F19: Régulier | G19: 1 | H19: 0 | I19: =tblJoueurs!$A19 -> 2 | J19: =tblJoueurs!$B19 -> 7 | K19: =tblJoueurs!$D19 & " " &tblJoueurs!$C19 -> Marie-Hélène Sarrasin | M19: 2 | N19: Julia Colpron | O19: 0
A20: 2 | B20: 8 | C20: Absent | D20: Absent | E20: Absent | F20: Remplaçant | G20: 1 | H20: 0 | I20: =tblJoueurs!$A20 -> 2 | J20: =tblJoueurs!$B20 -> 8 | K20: =tblJoueurs!$D20 & " " &tblJoueurs!$C20 -> Absent Absent | M20: 3 | N20: Isabelle Gamache | O20: 0
A21: 2 | B21: 9 | C21: Parenteau | D21: Vincent | E21: Vincent | F21: Régulier | G21: 1 | H21: 0 | I21: =tblJoueurs!$A21 -> 2 | J21: =tblJoueurs!$B21 -> 9 | K21: =tblJoueurs!$D21 & " " &tblJoueurs!$C21 -> Vincent Parenteau | M21: 4 | N21: Catherine Lachance | O21: 0
A22: 2 | B22: 10 | C22: Lecavalier | D22: Cindy | E22: Cindy | F22: Régulier | G22: 1 | H22: 0 | I22: =tblJoueurs!$A22 -> 2 | J22: =tblJoueurs!$B22 -> 10 | K22: =tblJoueurs!$D22 & " " &tblJoueurs!$C22 -> Cindy Lecavalier | M22: 5 | N22: Francis Vilandré | O22: 0
A23: 2 | B23: 99 | C23: Les Bons Perdants | D23: NA | E23: Les Bons Perdants | F23: Équipe | G23: 1 | H23: 0 | I23: =tblJoueurs!$A23 -> 2 | J23: =tblJoueurs!$B23 -> 99 | K23: =tblJoueurs!$D23 & " " &tblJoueurs!$C23 -> NA Les Bons Perdants | M23: 6 | N23: Julie Sarrazin | O23: 0
A24: 3 | B24: 1 | C24: Switzer | D24: Mark | E24: Mark | F24: Capitaine | G24: 1 | H24: 3 | I24: =tblJoueurs!$A24 -> 3 | J24: =tblJoueurs!$B24 -> 1 | K24: =tblJoueurs!$D24 & " " &tblJoueurs!$C24 -> Mark Switzer | M24: 7 | N24: Absent Absent | O24: 0
A25: 3 | B25: 2 | C25: Parent | D25: Pierre | E25: Pierre | F25: Régulier | G25: 1 | H25: 1 | I25: =tblJoueurs!$A25 -> 3 | J25: =tblJoueurs!$B25 -> 2 | K25: =tblJoueurs!$D25 & " " &tblJoueurs!$C25 -> Pierre Parent | M25: 8 | N25: Émilie Fougères | O25: 0
A26: 3 | B26: 3 | C26: Rivest | D26: François | E26: François | F26: Régulier | G26: 1 | H26: 2 | I26: =tblJoueurs!$A26 -> 3 | J26: =tblJoueurs!$B26 -> 3 | K26: =tblJoueurs!$D26 & " " &tblJoueurs!$C26 -> François Rivest | M26: 9 | N26: Marc-Olivier Loiselle | O26: 0
A27: 3 | B27: 4 | C27: Delage | D27: André | E27: André | F27: Régulier | G27: 1 | H27: 0 | I27: =tblJoueurs!$A27 -> 3 | J27: =tblJoueurs!$B27 -> 4 | K27: =tblJoueurs!$D27 & " " &tblJoueurs!$C27 -> André Delage
A28: 3 | B28: 5 | C28: Maheux | D28: Louise | E28: Louise | F28: Remplaçant | G28: 1 | H28: 0 | I28: =tblJoueurs!$A28 -> 3 | J28: =tblJoueurs!$B28 -> 5 | K28: =tblJoueurs!$D28 & " " &tblJoueurs!$C28 -> Louise Maheux
A29: 3 | B29: 6 | C29: Aubé | D29: Yanick | E29: Yanick | F29: Remplaçant | G29: 1 | H29: 0 | I29: =tblJoueurs!$A29 -> 3 | J29: =tblJoueurs!$B29 -> 6 | K29: =tblJoueurs!$D29 & " " &tblJoueurs!$C29 -> Yanick Aubé
A30: 3 | B30: 7 | C30: M. | D30: Jean-Michel | E30: Jean-Michel | F30: Remplaçant | G30: 1 | H30: 0 | I30: =tblJoueurs!$A30 -> 3 | J30: =tblJoueurs!$B30 -> 7 | K30: =tblJoueurs!$D30 & " " &tblJoueurs!$C30 -> Jean-Michel M.
A31: 3 | B31: 8 | C31: Absent | D31: Absent | E31: Absent | F31: Remplaçant | G31: 1 | H31: 0 | I31: =tblJoueurs!$A31 -> 3 | J31: =tblJoueurs!$B31 -> 8 | K31: =tblJoueurs!$D31 & " " &tblJoueurs!$C31 -> Absent Absent
A32: 3 | B32: 99 | C32: Les érudits en gerbe | D32: NA | E32: Les érudits en gerbe | F32: Équipe | G32: 1 | H32: 0 | I32: =tblJoueurs!$A32 -> 3 | J32: =tblJoueurs!$B32 -> 99 | K32: =tblJoueurs!$D32 & " " &tblJoueurs!$C32 -> NA Les érudits en gerbe
A33: 4 | B33: 1 | C33: Landry | D33: Sébastien | E33: Sébastien | F33: Capitaine | G33: 1 | H33: 1 | I33: =tblJoueurs!$A33 -> 4 | J33: =tblJoueurs!$B33 -> 1 | K33: =tblJoueurs!$D33 & " " &tblJoueurs!$C33 -> Sébastien Landry
A34: 4 | B34: 2 | C34: Bédard | D34: Frédéric | E34: Frédéric | F34: Régulier | G34: 1 | H34: 4 | I34: =tblJoueurs!$A34 -> 4 | J34: =tblJoueurs!$B34 -> 2 | K34: =tblJoueurs!$D34 & " " &tblJoueurs!$C34 -> Frédéric Bédard
A35: 4 | B35: 3 | C35: Ouellet | D35: Geneviève | E35: Geneviève | F35: Régulier | G35: 1 | H35: 2 | I35: =tblJoueurs!$A35 -> 4 | J35: =tblJoueurs!$B35 -> 3 | K35: =tblJoueurs!$D35 & " " &tblJoueurs!$C35 -> Geneviève Ouellet
A36: 4 | B36: 4 | C36: Vézina | D36: Samuel | E36: Samuel | F36: Régulier | G36: 1 | H36: 0 | I36: =tblJoueurs!$A36 -> 4 | J36: =tblJoueurs!$B36 -> 4 | K36: =tblJoueurs!$D36 & " " &tblJoueurs!$C36 -> Samuel Vézina
A37: 4 | B37: 5 | C37: Morency | D37: Jean-Dominique | E37: Jean-Dominique | F37: Remplaçant | G37: 1 | H37: 0 | I37: =tblJoueurs!$A37 -> 4 | J37: =tblJoueurs!$B37 -> 5 | K37: =tblJoueurs!$D37 & " " &tblJoueurs!$C37 -> Jean-Dominique Morency
A38: 4 | B38: 6 | C38: Martineau | D38: Stéphane | E38: Stéphane | F38: Remplaçant | G38: 1 | H38: 3 | I38: =tblJoueurs!$A38 -> 4 | J38: =tblJoueurs!$B38 -> 6 | K38: =tblJoueurs!$D38 & " " &tblJoueurs!$C38 -> Stéphane Martineau
... A78: 7 | B78: 99 | C78: Les Faciles à cuire | D78: NA | E78: Les Faciles à cuire | F78: Équipe | G78: 1 | H78: 0 | I78: =tblJoueurs!$A78 -> 7 | J78: =tblJoueurs!$B78 -> 99 | K78: =tblJoueurs!$D78 & " " &tblJoueurs!$C78 -> NA Les Faciles à cuire
I79: =tblJoueurs!$A79 -> 0 | J79: =tblJoueurs!$B79 -> 0 | K79: =tblJoueurs!$D79 & " " &tblJoueurs!$C79
...

Sheet Feuil2
A1: NoÉquipe | B1: NoJoueur | C1: NomJoueur | D1: PrénomJoueur | E1: Alias | F1: Statut | G1: Icône | H1: PosActuelle
A2: 1 | B2: 7 | C2: Absent | D2: Absent | E2: Absent | F2: Remplaçant | G2: 1 | H2: 0
A3: 1 | B3: 99 | C3: Les Génies de la traduction | D3: NA | E3: Les Génies de la traduction | F3: Équipe | G3: 1 | H3: 0
A4: 7 | B4: 6 | C4: Turpin | D4: Danielle | E4: Danielle | F4: Remplaçant | G4: 1 | H4: 0
A5: 2 | B5: 7 | C5: Sarrasin | D5: Marie-Hélène | E5: Marie-Hélène | F5: Régulier | G5: 1 | H5: 0
A6: 6 | B6: 7 | C6: Allard Gervais | D6: Daphné | E6: Daphné | F6: Remplaçant | G6: 1 | H6: 0
A7: 7 | B7: 9 | C7: NA | D7: Catherine | E7: Catherine | F7: Remplaçant | G7: 1 | H7: 0
A8: 3 | B8: 6 | C8: Aubé | D8: Yanick | E8: Yanick | F8: Remplaçant | G8: 1 | H8: 0
A9: 7 | B9: 10 | C9: NA | D9: Louis | E9: Louis | F9: Remplaçant | G9: 1 | H9: 0
A10: 3 | B10: 7 | C10: M. | D10: Jean-Michel | E10: Jean-Michel | F10: Remplaçant | G10: 1 | H10: 0
A11: 7 | B11: 7 | C11: Falconer | D11: James | E11: James | F11: Remplaçant | G11: 1 | H11: 0
A12: 6 | B12: 4 | C12: Charbonneau | D12: Patrick | E12: Patrick | F12: Régulier | G12: 1 | H12: 0
A13: 6 | B13: 8 | C13: Bourdages | D13: Emy | E13: Emy | F13: Remplaçant | G13: 1 | H13: 0
... A73: 6 | B73: 12 | C73: Bouchard-Santerre | D73: Arnaud | E73: Arnaud | F73: Remplaçant | G73: 1 | H73: 0
